Workbook

Sheet Dashboard
B2: SALES PERFORMANCE & CUSTOMER INSIGHTS DASHBOARD
B3: FY 2025 | All figures below update automatically from the Analysis sheet
B6: TOTAL SALES | D6: TOTAL ORDERS | F6: TOTAL CUSTOMERS | H6: AVG ORDER VALUE | J6: TOTAL QUANTITY SOLD
B7: =Analysis!B5 -> 9033089.4 | D7: =Analysis!B6 -> 1246 | F7: =Analysis!B9 -> 778 | H7: =Analysis!B8 -> 7249.6704 | J7: =Analysis!B7 -> 2592
B10: TRENDS & BREAKDOWNS
B64: Data source: Clean_Data sheet (1,246 cleaned records, Jan-Dec 2025) | Built with Excel formulas - fully recalculates on data change

Sheet Raw_Data
A1: Order_ID | B1: Order_Date | C1: Customer_ID | D1: Customer_Name | E1: Gender | F1: Age | G1: City | H1: State | I1: Product_Category | J1: Product | K1: Quantity | L1: Unit_Price | M1: Discount | N1: Sales | O1: Payment_Mode | P1: Sales_Channel
A2: ORD00596 | B2: 2025-11-11 | C2: CUST0372 | D2: Vivek Menon | E2: Male | F2: 42 | G2: Noida | H2: Uttar Pradesh | I2: Books & Stationery | J2: Desk Organizer | K2: 3 | L2: 680.19 | M2: 0.15 | N2: 1734.48 | O2: Credit Card | P2: In-Store
A3: ORD01250 | B3: 2025-06-21 | C3: CUST0779 | D3: Ritu Bose | E3: Female | F3: 62 | G3: Bengaluru | H3: Karnataka | I3: Groceries | J3: Cooking Oil 1L | K3: 1 | L3: 289.86 | M3: 0.05 | N3: 275.37 | O3: Credit Card | P3: Mobile App
A4: ORD00520 | B4: 2025-06-17 | C4: CUST0267 | D4: Neha Malhotra | E4: Female | F4: 31 | G4: Rohini | H4: Delhi | I4: Sports & Fitness | J4: Cricket Bat | K4: 1 | L4: 2322.67 | M4: 0.1 | N4: 2090.4 | O4: UPI | P4: In-Store
A5: ORD00265 | B5: 2025-02-15 | C5: CUST0165 | D5: Praveen Gupta | E5: Male | F5: 49 | G5: Mysuru | H5: Karnataka | I5: Sports & Fitness | J5: Yoga Mat | K5: 5 | L5: 661.03 | M5: 0 | N5: 3305.15 | O5: Cash on Delivery | P5: In-Store
A6: ORD00303 | B6: 2025-05-01 | C6: CUST0189 | D6: Deepak Choudhury | E6: Male | F6: 36 | G6: Bengaluru | H6: Karnataka | I6: Books & Stationery | J6: Backpack | K6: 2 | L6: 2975.8 | M6: 0.05 | N6: 5654.02 | O6: Credit Card | P6: In-Store
A7: ORD00579 | B7: 2025-12-26 | C7: CUST0363 | D7: Arjun Sharma | E7: Male | F7: 53 | G7: Kozhikode | H7: Kerala | I7: Sports & Fitness | J7: Dumbbell Set | K7: 5 | L7: 5080.71 | M7: 0 | N7: 25403.55 | O7: Cash on Delivery | P7: Online
A8: ORD01158 | B8: 2025-01-22 | C8: CUST0719 | D8: Swati Iyer | E8: Female | F8: 21 | G8: Kozhikode | H8: Kerala | I8: Books & Stationery | J8: Notebook Set | K8: 3 | L8: 119.99 | M8: 0 | N8: 359.97 | O8: Credit Card | P8: Mobile App
A9: ORD00372 | B9: 2025-05-16 | C9: CUST0192 | D9: Manisha Nair | E9: Female | F9: 64 | G9: Pune | H9: Maharashtra | I9: Sports & Fitness | J9: Dumbbell Set | K9: 1 | L9: 3245 | M9: 0.15 | N9: 2758.25 | O9: Debit Card | P9: Online
A10: ORD01128 | B10: 2025-07-12 | C10: CUST0205 | D10: Rahul Verma | E10: Male | F10: 46 | G10: Mangaluru | H10: Karnataka | I10: Beauty & Personal Care | J10: Trimmer | K10: 2 | L10: 1515.02 | M10: 0 | N10: 3030.04 | O10: Debit Card | P10: Mobile App
A11: ORD00995 | B11: 2025-06-26 | C11: CUST0624 | D11: Ravi Nair | E11: Male | F11: 43 | G11: Nizamabad | H11: Telangana | I11: Groceries | J11: Spice Combo | K11: 2 | L11: 876.41 | M11: 0.1 | N11: 1577.54 | O11: Credit Card | P11: In-Store
A12: ORD00461 | B12: 2025-02-03 | C12: CUST0291 | D12: Shreya Das | E12: Female | F12: 29 | G12: Guntur | H12: Andhra Pradesh | I12: Home & Kitchen | J12: Water Bottle Set | K12: 1 | L12: 1074.57 | M12: 0.05 | N12: 1020.84 | O12: UPI | P12: Online
A13: ORD00034 | B13: 2025-10-03 | C13: CUST0019 | D13: Manisha Agarwal | E13: Female | F13: 25 | G13: Vadodara | H13: Gujarat | I13: Clothing | J13: Formal Shirt | K13: 1 | L13: 556.75 | M13: 0.1 | N13: 501.07 | O13: UPI | P13: Mobile App
... A35: ORD00407 | B35: 2025-10-09 | C35: CUST0257 | D35: Divya Bose | E35: Female | F35: 40 | G35: Thiruvananthapuram | H35: Kerala | I35: Sports & Fitness | J35: Fitness Band | K35: 1 | L35: 2494.19 | M35: 0.15 | N35: 2120.06 | O35: UPI | P35: Online
A36: ORD01201 | B36: 2025-09-24 | C36: CUST0750 | E36: Male | F36: 61 | H36: Kerala | I36: Sports & Fitness | J36: Football | K36: 1 | L36: 1007.75 | N36: 957.36 | P36: In-Store
A37: ORD00072 | B37: 2025-08-25 | C37: CUST0036 | D37: Aishwarya Reddy | E37: Female | F37: 29 | G37: Kanpur | H37: Uttar Pradesh | I37: Electronics | J37: Power Bank | K37: 5 | L37: 685.51 | M37: 0.2 | N37: 2742.04 | O37: Cash on Delivery | P37: In-Store
A38: ORD00997 | B38: 2025-04-22 | C38: CUST0626 | D38: Kritika Pillai | E38: Female | F38: 33 | G38: Vadodara | H38: Gujarat | I38: Clothing | J38: Sports Shoes | K38: 3 | L38: 3731.65 | M38: 0 | N38: 11194.95 | O38: Debit Card | P38: Online
A39: ORD01114 | B39: 2025-08-20 | C39: CUST0642 | D39: Divya Patel | E39: Female | F39: 33 | G39: Mysuru | H39: Karnataka | I39: Home & Kitchen | J39: Non-Stick Cookware Set | K39: 1 | L39: 4767.47 | M39: 0.05 | N39: 4529.1 | O39: UPI | P39: Online
A40: ORD00369 | B40: 2025-10-28 | C40: CUST0232 | D40: Rekha Das | E40: Female | F40: 54 | G40: Lucknow | H40: Uttar Pradesh | I40: Groceries | J40: Atta 10kg | K40: 2 | L40: 685.43 | M40: 0.05 | N40: 1302.32 | O40: Cash on Delivery | P40: In-Store
A41: ORD01062 | B41: 2025-05-22 | C41: CUST0664 | D41: Amit Das | E41: Male | F41: 28 | G41: Thiruvananthapuram | H41: Kerala | I41: Beauty & Personal Care | J41: Skincare Kit | K41: 3 | L41: 1321.3 | M41: 0 | N41: 3963.9 | O41: Credit Card | P41: Online
A42: ORD01203 | B42: 2025-01-02 | C42: CUST0074 | D42: Karthik Reddy | E42: Male | F42: 36 | G42: Kanpur | H42: Uttar Pradesh | I42: Home & Kitchen | J42: Mixer Grinder | K42: 3 | L42: 6332.54 | M42: 0.25 | N42: 14248.22 | O42: Credit Card | P42: Mobile App
A43: ORD00110 | B43: 2025-11-18 | C43: CUST0066 | D43: Aditya Kumar | E43: Male | F43: 34 | G43: New Delhi | H43: Delhi | I43: Books & Stationery | J43: Novel | K43: 2 | L43: 719.16 | M43: 0 | N43: 1438.32 | O43: UPI | P43: Mobile App
A44: ORD00430 | B44: 2025-11-06 | C44: CUST0014 | D44: Anil Rao | E44: Male | F44: 50 | G44: Chennai | H44: Tamil Nadu | I44: Home & Kitchen | J44: Mixer Grinder | K44: 2 | L44: 4940.39 | M44: 0.1 | N44: 8892.7 | O44: UPI | P44: In-Store
A45: ORD00722 | B45: 2025-10-01 | C45: CUST0132 | D45: Manoj Malhotra | E45: Male | F45: 45 | G45: Lucknow | H45: Uttar Pradesh | I45: Sports & Fitness | J45: Badminton Racket | K45: 2 | L45: 2688.41 | M45: 0.1 | N45: 4839.14 | O45: UPI | P45: In-Store
A46: ORD00546 | B46: 2025-01-21 | C46: CUST0343 | D46: Divya Mehta | E46: Female | F46: 25 | G46: Lucknow | H46: Uttar Pradesh | I46: Books & Stationery | J46: Novel | K46: 1 | L46: 520.86 | M46: 0 | N46: 520.86 | O46: Credit Card | P46: In-Store
A47: ORD01018 | B47: 2025-04-08 | C47: CUST0468 | D47: Divya Reddy | E47: Female | F47: 26 | G47: Chandigarh | H47: Punjab | I47: Clothing | J47: Men's T-Shirt | K47: 1 | L47: 1181.42 | M47: 0 | N47: 1181.42 | O47: Net Banking | P47: Mobile App
A48: ORD01136 | B48: 2025-03-24 | C48: CUST0706 | D48: Neha Choudhury | E48: Female | F48: 34 | G48: Siliguri | H48: West Bengal | I48: Clothing | J48: Men's T-Shirt | K48: 5 | L48: 889.01 | M48: 0 | N48: 4445.05 | O48: Credit Card | P48: Online
... A266: ORD00240 | B266: 2025-09-12 | C266: CUST0150 | D266: Divya Sharma | E266: Female | F266: 39 | G266: Surat | H266: Gujarat | I266: Books & Stationery | J266: Notebook Set | K266: 5 | L266: 204.18 | M266: 0.1 | N266: 918.81 | O266: UPI | P266: Online
A267: ORD01106 | B267: 2025-04-07 | C267: CUST0690 | E267: Male | F267: 41 | H267: Uttar Pradesh | I267: Clothing | J267: Kids Wear | K267: 1 | L267: 1016 | N267: 812.8 | P267: In-Store
A268: ORD00164 | B268: 20/01/2025 | C268: CUST0008 | D268: Vikram Pillai | E268: Male | F268: 22 | G268: Jaipur | H268: Rajasthan | I268: Groceries | J268: Rice 5kg | K268: 1 | L268: 625.15 | M268: 0.15 | N268: 531.38 | O268: Cash on Delivery | P268: Online
A269: ORD00120 | B269: 2025-11-09 | C269: CUST0057 | D269: Vivek Das | E269: Male | F269: 45 | G269: Kochi | H269: Kerala | I269: Electronics | J269: Power Bank | K269: 3 | L269: 1227.96 | M269: 0.25 | N269: 2762.91 | O269: Debit Card | P269: In-Store
A270: ORD00873 | B270: 2025-02-24 | C270: CUST0547 | D270: Ravi Sharma | E270: Male | F270: 47 | G270: Udaipur | H270: Rajasthan | I270: Groceries | J270: Rice 5kg | K270: 1 | L270: 341.33 | M270: 0.25 | N270: 256 | O270: Debit Card | P270: Online
A271: ORD00654 | B271: 2025-07-30 | C271: CUST0347 | D271: Shreya Pillai | E271: Female | F271: 60 | G271: Ludhiana | H271: Punjab | I271: Electronics | J271: Smartphone | K271: 1 | L271: 18911.92 | M271: 0 | N271: 18911.92 | O271: Debit Card | P271: In-Store
A272: ORD00813 | B272: 2025-04-19 | C272: CUST0509 | D272: Manoj Bose | E272: Male | F272: 20 | G272: Ludhiana | H272: Punjab | I272: Electronics | J272: LED Monitor | K272: 5 | L272: 18632.95 | M272: 0 | N272: 93164.75 | O272: Cash on Delivery | P272: Mobile App
A273: ORD00213 | B273: 2025-02-02 | C273: CUST0110 | D273: Kritika Das | E273: Female | F273: 32 | G273: Dwarka | H273: Delhi | I273: Beauty & Personal Care | J273: Face Wash | K273: 1 | L273: 451.37 | M273: 0.15 | N273: 383.66 | O273: UPI | P273: Mobile App
A274: ORD00118 | B274: 2025-10-04 | C274: CUST0018 | D274: Arjun Rao | E274: Male | F274: 43 | G274: Howrah | H274: West Bengal | I274: Clothing | J274: Women's Kurti | K274: 3 | L274: 931.72 | M274: 0.1 | N274: 2515.64 | O274: Cash on Delivery | P274: Mobile App
A275: ORD00866 | B275: 2025-01-28 | C275: CUST0542 | D275: Naveen Pillai | E275: Male | F275: 36 | G275: Pune | H275: Maharashtra | I275: Electronics | J275: Wireless Mouse | K275: 1 | L275: 360.47 | M275: 0.1 | N275: 324.42 | O275: UPI | P275: Online
A276: ORD01086 | B276: 2025-03-03 | C276: CUST0616 | D276: Sneha Nair | E276: Female | F276: 44 | G276: Bengaluru | H276: Karnataka | I276: Groceries | J276: Cooking Oil 1L | K276: 1 | L276: 266.15 | M276: 0.2 | N276: 212.92 | O276: Debit Card | P276: Online
A277: ORD00313 | B277: 2025-12-03 | C277: CUST0058 | D277: Anjali Kapoor | E277: Female | F277: 51 | G277: Coimbatore | H277: Tamil Nadu | I277: Groceries | J277: Tea Pack | K277: 3 | L277: 231.79 | M277: 0.1 | N277: 625.83 | O277: UPI | P277: In-Store
A278: ORD01213 | B278: 2025-05-29 | C278: CUST0414 | D278: Kiran Das | E278: Male | F278: 47 | G278: Vadodara | H278: Gujarat | I278: Clothing | J278: Winter Jacket | K278: 1 | L278: 2099.06 | M278: 0 | N278: 2099.06 | O278: Cash on Delivery | P278: Online
...

Sheet Data_Cleaning
A1: DATA CLEANING REPORT
A2: Automated checks run against Raw_Data (formulas recalculate live)
A4: 1. Record Counts
A5: Total records in Raw_Data | B5: =COUNTA(Raw_Data!A2:A1263) -> 1262 | C5: Includes duplicates & bad rows
A6: Fully duplicated rows | B6: =SUMPRODUCT((COUNTIFS(Raw_Data!A2:A1263,Raw_Data!A2:A1263,Raw_Data!B2:B1263,Raw_Data!B2:B1263,Raw_Data!C2:C1263,Raw_Data!C2:C1263,Raw_Data!J2:J1263,Raw_Data!J2:J1263)>1)*1) -> 24 | C6: Rows identical on Order_ID, Date, Customer & Product
A7: Duplicate Order_IDs | B7: =SUMPRODUCT((COUNTIF(Raw_Data!A2:A1263,Raw_Data!A2:A1263)>1)*1) -> 32 | C7: Same Order_ID appearing more than once
A9: 2. Missing Values by Column
A10: Column | B10: Missing Count | C10: Notes
A11: Customer_Name | B11: =COUNTBLANK(Raw_Data!D2:D1263) -> 13
A12: City | B12: =COUNTBLANK(Raw_Data!G2:G1263) -> 13
A13: Payment_Mode | B13: =COUNTBLANK(Raw_Data!O2:O1263) -> 13
A14: Discount | B14: =COUNTBLANK(Raw_Data!M2:M1263) -> 13
A15: Age | B15: =COUNTBLANK(Raw_Data!F2:F1263) -> 0
A16: Order_Date | B16: =COUNTBLANK(Raw_Data!B2:B1263) -> 0
A18: 3. Invalid / Out-of-Range Values
A19: Invalid Age (<15 or >90) | B19: =COUNTIFS(Raw_Data!F2:F1263,"<15")+COUNTIFS(Raw_Data!F2:F1263,">90") -> 5
A20: Negative or zero Sales | B20: =COUNTIF(Raw_Data!N2:N1263,"<=0") -> 0
A21: Order_Date not in YYYY-MM-DD format | B21: =SUMPRODUCT((MID(Raw_Data!B2:B1263,5,1)<>"-")*1) -> 6
A23: 4. Before vs. After Cleaning
A24: Total records BEFORE cleaning | B24: =COUNTA(Raw_Data!A2:A1263) -> 1262
A25: Total records AFTER cleaning | B25: =COUNTA(Clean_Data!A2:A1247) -> 1246
A26: Records removed / corrected | B26: =B24-B25 -> 16
A28: 5. Cleaning Steps Applied (see python/sales_analysis.py)
A29: - Removed fully duplicated rows.
A30: - Standardized Order_Date to YYYY-MM-DD (source had DD/MM/YYYY and MM-DD-YYYY variants).
A31: - Removed duplicate Order_IDs, keeping the first occurrence.
A32: - Replaced invalid ages (<15 or >90) with the median customer age.
A33: - Filled missing Customer_Name/City with 'Unknown', missing Payment_Mode with 'Unknown'.
A34: - Filled missing Discount with 0 (assumed no discount applied).
A35: - Recalculated Sales = Quantity x Unit_Price x (1 - Discount) for every row to guarantee formula integrity.

Sheet Clean_Data
A1: Order_ID | B1: Order_Date | C1: Customer_ID | D1: Customer_Name | E1: Gender | F1: Age | G1: City | H1: State | I1: Product_Category | J1: Product | K1: Quantity | L1: Unit_Price | M1: Discount | N1: Sales | O1: Payment_Mode | P1: Sales_Channel | Q1: Order_Month
A2: ORD00596 | B2: 2025-11-11 | C2: CUST0372 | D2: Vivek Menon | E2: Male | F2: 42 | G2: Noida | H2: Uttar Pradesh | I2: Books & Stationery | J2: Desk Organizer | K2: 3 | L2: 680.19 | M2: 0.15 | N2: 1734.48 | O2: Credit Card | P2: In-Store | Q2: 2025-11
A3: ORD01250 | B3: 2025-06-21 | C3: CUST0779 | D3: Ritu Bose | E3: Female | F3: 62 | G3: Bengaluru | H3: Karnataka | I3: Groceries | J3: Cooking Oil 1L | K3: 1 | L3: 289.86 | M3: 0.05 | N3: 275.37 | O3: Credit Card | P3: Mobile App | Q3: 2025-06
A4: ORD00520 | B4: 2025-06-17 | C4: CUST0267 | D4: Neha Malhotra | E4: Female | F4: 31 | G4: Rohini | H4: Delhi | I4: Sports & Fitness | J4: Cricket Bat | K4: 1 | L4: 2322.67 | M4: 0.1 | N4: 2090.4 | O4: UPI | P4: In-Store | Q4: 2025-06
A5: ORD00265 | B5: 2025-02-15 | C5: CUST0165 | D5: Praveen Gupta | E5: Male | F5: 49 | G5: Mysuru | H5: Karnataka | I5: Sports & Fitness | J5: Yoga Mat | K5: 5 | L5: 661.03 | M5: 0 | N5: 3305.15 | O5: Cash on Delivery | P5: In-Store | Q5: 2025-02
A6: ORD00303 | B6: 2025-05-01 | C6: CUST0189 | D6: Deepak Choudhury | E6: Male | F6: 36 | G6: Bengaluru | H6: Karnataka | I6: Books & Stationery | J6: Backpack | K6: 2 | L6: 2975.8 | M6: 0.05 | N6: 5654.02 | O6: Credit Card | P6: In-Store | Q6: 2025-05
A7: ORD00579 | B7: 2025-12-26 | C7: CUST0363 | D7: Arjun Sharma | E7: Male | F7: 53 | G7: Kozhikode | H7: Kerala | I7: Sports & Fitness | J7: Dumbbell Set | K7: 5 | L7: 5080.71 | M7: 0 | N7: 25403.55 | O7: Cash on Delivery | P7: Online | Q7: 2025-12
A8: ORD01158 | B8: 2025-01-22 | C8: CUST0719 | D8: Swati Iyer | E8: Female | F8: 21 | G8: Kozhikode | H8: Kerala | I8: Books & Stationery | J8: Notebook Set | K8: 3 | L8: 119.99 | M8: 0 | N8: 359.97 | O8: Credit Card | P8: Mobile App | Q8: 2025-01
A9: ORD00372 | B9: 2025-05-16 | C9: CUST0192 | D9: Manisha Nair | E9: Female | F9: 64 | G9: Pune | H9: Maharashtra | I9: Sports & Fitness | J9: Dumbbell Set | K9: 1 | L9: 3245 | M9: 0.15 | N9: 2758.25 | O9: Debit Card | P9: Online | Q9: 2025-05
A10: ORD01128 | B10: 2025-07-12 | C10: CUST0205 | D10: Rahul Verma | E10: Male | F10: 46 | G10: Mangaluru | H10: Karnataka | I10: Beauty & Personal Care | J10: Trimmer | K10: 2 | L10: 1515.02 | M10: 0 | N10: 3030.04 | O10: Debit Card | P10: Mobile App | Q10: 2025-07
A11: ORD00995 | B11: 2025-06-26 | C11: CUST0624 | D11: Ravi Nair | E11: Male | F11: 43 | G11: Nizamabad | H11: Telangana | I11: Groceries | J11: Spice Combo | K11: 2 | L11: 876.41 | M11: 0.1 | N11: 1577.54 | O11: Credit Card | P11: In-Store | Q11: 2025-06
A12: ORD00461 | B12: 2025-02-03 | C12: CUST0291 | D12: Shreya Das | E12: Female | F12: 29 | G12: Guntur | H12: Andhra Pradesh | I12: Home & Kitchen | J12: Water Bottle Set | K12: 1 | L12: 1074.57 | M12: 0.05 | N12: 1020.84 | O12: UPI | P12: Online | Q12: 2025-02
A13: ORD00034 | B13: 2025-10-03 | C13: CUST0019 | D13: Manisha Agarwal | E13: Female | F13: 25 | G13: Vadodara | H13: Gujarat | I13: Clothing | J13: Formal Shirt | K13: 1 | L13: 556.75 | M13: 0.1 | N13: 501.08 | O13: UPI | P13: Mobile App | Q13: 2025-10
... A1247: ORD00907 | B1247: 2025-07-03 | C1247: CUST0184 | D1247: Vivek Rao | E1247: Male | F1247: 50 | G1247: Nagpur | H1247: Maharashtra | I1247: Beauty & Personal Care | J1247: Trimmer | K1247: 1 | L1247: 735.28 | M1247: 0 | N1247: 735.28 | O1247: UPI | P1247: Mobile App | Q1247: 2025-07

Sheet Analysis
A1: SALES ANALYSIS | T1: Helper: Product totals (used for Top 10 ranking - do not delete) | X1: Helper: Customer totals (used for Top 10 ranking - do not delete)
A2: All figures calculated live with formulas from Clean_Data | T2: Product | U2: Total_Sales | V2: Rank | X2: Customer_ID | Y2: Customer_Name | Z2: Total_Sales | AA2: Rank
T3: Air Fryer | U3: =SUMIFS(Clean_Data!N2:N1247,Clean_Data!J2:J1247,T3) -> 290461.46 | V3: =RANK(U3,$U$3:$U$47)+COUNTIF($U$3:U3,U3)-1 -> 5 | X3: CUST0001 | Y3: Arjun Nair | Z3: =SUMIFS(Clean_Data!N2:N1247,Clean_Data!C2:C1247,X3) -> 85857.96 | AA3: =RANK(Z3,$Z$3:$Z$780)+COUNTIF($Z$3:Z3,Z3)-1 -> 21
A4: 1. Key Performance Indicators | E4: 7. Top 10 Products | T4: Atta 10kg | U4: =SUMIFS(Clean_Data!N2:N1247,Clean_Data!J2:J1247,T4) -> 34298 | V4: =RANK(U4,$U$3:$U$47)+COUNTIF($U$3:U4,U4)-1 -> 38 | X4: CUST0002 | Y4: Manisha Nair | Z4: =SUMIFS(Clean_Data!N2:N1247,Clean_Data!C2:C1247,X4) -> 10532.81 | AA4: =RANK(Z4,$Z$3:$Z$780)+COUNTIF($Z$3:Z4,Z4)-1 -> 171
A5: Total Sales (Rs.) | B5: =SUM(Clean_Data!N2:N1247) -> 9033089.4 | E5: Rank | F5: Product | G5: Total Sales | T5: Backpack | U5: =SUMIFS(Clean_Data!N2:N1247,Clean_Data!J2:J1247,T5) -> 136320 | V5: =RANK(U5,$U$3:$U$47)+COUNTIF($U$3:U5,U5)-1 -> 15 | X5: CUST0003 | Y5: Rohit Iyer | Z5: =SUMIFS(Clean_Data!N2:N1247,Clean_Data!C2:C1247,X5) -> 1740.6 | AA5: =RANK(Z5,$Z$3:$Z$780)+COUNTIF($Z$3:Z5,Z5)-1 -> 536
A6: Total Orders | B6: =COUNTA(Clean_Data!A2:A1247) -> 1246 | E6: 1 | F6: =INDEX($T$3:$T$47,MATCH(E6,$V$3:$V$47,0)) -> Laptop | G6: =INDEX($U$3:$U$47,MATCH(E6,$V$3:$V$47,0)) -> 2471093.4 | T6: Badminton Racket | U6: =SUMIFS(Clean_Data!N2:N1247,Clean_Data!J2:J1247,T6) -> 133586.87 | V6: =RANK(U6,$U$3:$U$47)+COUNTIF($U$3:U6,U6)-1 -> 17 | X6: CUST0004 | Y6: Manoj Reddy | Z6: =SUMIFS(Clean_Data!N2:N1247,Clean_Data!C2:C1247,X6) -> 79420.12 | AA6: =RANK(Z6,$Z$3:$Z$780)+COUNTIF($Z$3:Z6,Z6)-1 -> 26
A7: Total Quantity Sold | B7: =SUM(Clean_Data!K2:K1247) -> 2592 | E7: 2 | F7: =INDEX($T$3:$T$47,MATCH(E7,$V$3:$V$47,0)) -> Tablet | G7: =INDEX($U$3:$U$47,MATCH(E7,$V$3:$V$47,0)) -> 1243905.4 | T7: Bed Sheet Set | U7: =SUMIFS(Clean_Data!N2:N1247,Clean_Data!J2:J1247,T7) -> 68571.59 | V7: =RANK(U7,$U$3:$U$47)+COUNTIF($U$3:U7,U7)-1 -> 24 | X7: CUST0005 | Y7: Pooja Nair | Z7: =SUMIFS(Clean_Data!N2:N1247,Clean_Data!C2:C1247,X7) -> 2566.47 | AA7: =RANK(Z7,$Z$3:$Z$780)+COUNTIF($Z$3:Z7,Z7)-1 -> 457
A8: Average Order Value (Rs.) | B8: =B5/B6 -> 7249.6704 | E8: 3 | F8: =INDEX($T$3:$T$47,MATCH(E8,$V$3:$V$47,0)) -> Smartphone | G8: =INDEX($U$3:$U$47,MATCH(E8,$V$3:$V$47,0)) -> 808881.96 | T8: Bluetooth Earbuds | U8: =SUMIFS(Clean_Data!N2:N1247,Clean_Data!J2:J1247,T8) -> 154534.71 | V8: =RANK(U8,$U$3:$U$47)+COUNTIF($U$3:U8,U8)-1 -> 12 | X8: CUST0006 | Y8: Sunita Nair | Z8: =SUMIFS(Clean_Data!N2:N1247,Clean_Data!C2:C1247,X8) -> 13001.63 | AA8: =RANK(Z8,$Z$3:$Z$780)+COUNTIF($Z$3:Z8,Z8)-1 -> 146
A9: Total Customers | B9: =SUMPRODUCT((COUNTIF(Clean_Data!C2:C1247,Clean_Data!C2:C1247))^-1) -> 778 | E9: 4 | F9: =INDEX($T$3:$T$47,MATCH(E9,$V$3:$V$47,0)) -> LED Monitor | G9: =INDEX($U$3:$U$47,MATCH(E9,$V$3:$V$47,0)) -> 787030.26 | T9: Cooking Oil 1L | U9: =SUMIFS(Clean_Data!N2:N1247,Clean_Data!J2:J1247,T9) -> 14113.52 | V9: =RANK(U9,$U$3:$U$47)+COUNTIF($U$3:U9,U9)-1 -> 45 | X9: CUST0007 | Y9: Karthik Joshi | Z9: =SUMIFS(Clean_Data!N2:N1247,Clean_Data!C2:C1247,X9) -> 18346.31 | AA9: =RANK(Z9,$Z$3:$Z$780)+COUNTIF($Z$3:Z9,Z9)-1 -> 103
A10: Average Discount | B10: =AVERAGE(Clean_Data!M2:M1247) -> 0.083346709 | E10: 5 | F10: =INDEX($T$3:$T$47,MATCH(E10,$V$3:$V$47,0)) -> Air Fryer | G10: =INDEX($U$3:$U$47,MATCH(E10,$V$3:$V$47,0)) -> 290461.46 | T10: Cricket Bat | U10: =SUMIFS(Clean_Data!N2:N1247,Clean_Data!J2:J1247,T10) -> 133689.24 | V10: =RANK(U10,$U$3:$U$47)+COUNTIF($U$3:U10,U10)-1 -> 16 | X10: CUST0008 | Y10: Vikram Pillai | Z10: =SUMIFS(Clean_Data!N2:N1247,Clean_Data!C2:C1247,X10) -> 6098.24 | AA10: =RANK(Z10,$Z$3:$Z$780)+COUNTIF($Z$3:Z10,Z10)-1 -> 251
E11: 6 | F11: =INDEX($T$3:$T$47,MATCH(E11,$V$3:$V$47,0)) -> Smartwatch | G11: =INDEX($U$3:$U$47,MATCH(E11,$V$3:$V$47,0)) -> 202601.63 | T11: Desk Organizer | U11: =SUMIFS(Clean_Data!N2:N1247,Clean_Data!J2:J1247,T11) -> 47145.98 | V11: =RANK(U11,$U$3:$U$47)+COUNTIF($U$3:U11,U11)-1 -> 32 | X11: CUST0009 | Y11: Naveen Das | Z11: =SUMIFS(Clean_Data!N2:N1247,Clean_Data!C2:C1247,X11) -> 14714.87 | AA11: =RANK(Z11,$Z$3:$Z$780)+COUNTIF($Z$3:Z11,Z11)-1 -> 130
A12: 2. Sales by Month | E12: 7 | F12: =INDEX($T$3:$T$47,MATCH(E12,$V$3:$V$47,0)) -> Dumbbell Set | G12: =INDEX($U$3:$U$47,MATCH(E12,$V$3:$V$47,0)) -> 201685.27 | T12: Dumbbell Set | U12: =SUMIFS(Clean_Data!N2:N1247,Clean_Data!J2:J1247,T12) -> 201685.27 | V12: =RANK(U12,$U$3:$U$47)+COUNTIF($U$3:U12,U12)-1 -> 7 | X12: CUST0010 | Y12: Anil Kumar | Z12: =SUMIFS(Clean_Data!N2:N1247,Clean_Data!C2:C1247,X12) -> 104574.56 | AA12: =RANK(Z12,$Z$3:$Z$780)+COUNTIF($Z$3:Z12,Z12)-1 -> 14
A13: Month | B13: Total Sales | E13: 8 | F13: =INDEX($T$3:$T$47,MATCH(E13,$V$3:$V$47,0)) -> Makeup Kit | G13: =INDEX($U$3:$U$47,MATCH(E13,$V$3:$V$47,0)) -> 189308.51 | T13: Face Wash | U13: =SUMIFS(Clean_Data!N2:N1247,Clean_Data!J2:J1247,T13) -> 21445.26 | V13: =RANK(U13,$U$3:$U$47)+COUNTIF($U$3:U13,U13)-1 -> 43 | X13: CUST0011 | Y13: Aditya Reddy | Z13: =SUMIFS(Clean_Data!N2:N1247,Clean_Data!C2:C1247,X13) -> 2772.47 | AA13: =RANK(Z13,$Z$3:$Z$780)+COUNTIF($Z$3:Z13,Z13)-1 -> 442
A14: 2025-01 | B14: =SUMIFS(Clean_Data!N2:N1247,Clean_Data!Q2:Q1247,A14) -> 421687.38 | E14: 9 | F14: =INDEX($T$3:$T$47,MATCH(E14,$V$3:$V$47,0)) -> Vacuum Cleaner | G14: =INDEX($U$3:$U$47,MATCH(E14,$V$3:$V$47,0)) -> 187571.99 | T14: Fitness Band | U14: =SUMIFS(Clean_Data!N2:N1247,Clean_Data!J2:J1247,T14) -> 155497.7 | V14: =RANK(U14,$U$3:$U$47)+COUNTIF($U$3:U14,U14)-1 -> 11 | X14: CUST0012 | Y14: Kiran Malhotra | Z14: =SUMIFS(Clean_Data!N2:N1247,Clean_Data!C2:C1247,X14) -> 4675.76 | AA14: =RANK(Z14,$Z$3:$Z$780)+COUNTIF($Z$3:Z14,Z14)-1 -> 321
A15: 2025-02 | B15: =SUMIFS(Clean_Data!N2:N1247,Clean_Data!Q2:Q1247,A15) -> 511227.4 | E15: 10 | F15: =INDEX($T$3:$T$47,MATCH(E15,$V$3:$V$47,0)) -> Mixer Grinder | G15: =INDEX($U$3:$U$47,MATCH(E15,$V$3:$V$47,0)) -> 178908.14 | T15: Football | U15: =SUMIFS(Clean_Data!N2:N1247,Clean_Data!J2:J1247,T15) -> 37982.57 | V15: =RANK(U15,$U$3:$U$47)+COUNTIF($U$3:U15,U15)-1 -> 35 | X15: CUST0013 | Y15: Sanjay Das | Z15: =SUMIFS(Clean_Data!N2:N1247,Clean_Data!C2:C1247,X15) -> 362.27 | AA15: =RANK(Z15,$Z$3:$Z$780)+COUNTIF($Z$3:Z15,Z15)-1 -> 745
A16: 2025-03 | B16: =SUMIFS(Clean_Data!N2:N1247,Clean_Data!Q2:Q1247,A16) -> 843389.82 | T16: Formal Shirt | U16: =SUMIFS(Clean_Data!N2:N1247,Clean_Data!J2:J1247,T16) -> 35959.06 | V16: =RANK(U16,$U$3:$U$47)+COUNTIF($U$3:U16,U16)-1 -> 36 | X16: CUST0014 | Y16: Anil Rao | Z16: =SUMIFS(Clean_Data!N2:N1247,Clean_Data!C2:C1247,X16) -> 23420.33 | AA16: =RANK(Z16,$Z$3:$Z$780)+COUNTIF($Z$3:Z16,Z16)-1 -> 86
A17: 2025-04 | B17: =SUMIFS(Clean_Data!N2:N1247,Clean_Data!Q2:Q1247,A17) -> 674455.53 | T17: Fountain Pen | U17: =SUMIFS(Clean_Data!N2:N1247,Clean_Data!J2:J1247,T17) -> 59726.97 | V17: =RANK(U17,$U$3:$U$47)+COUNTIF($U$3:U17,U17)-1 -> 28 | X17: CUST0015 | Y17: Anil Verma | Z17: =SUMIFS(Clean_Data!N2:N1247,Clean_Data!C2:C1247,X17) -> 24139.73 | AA17: =RANK(Z17,$Z$3:$Z$780)+COUNTIF($Z$3:Z17,Z17)-1 -> 84
A18: 2025-05 | B18: =SUMIFS(Clean_Data!N2:N1247,Clean_Data!Q2:Q1247,A18) -> 831932.07 | E18: 8. Top 10 Customers | T18: Hair Dryer | U18: =SUMIFS(Clean_Data!N2:N1247,Clean_Data!J2:J1247,T18) -> 80249.15 | V18: =RANK(U18,$U$3:$U$47)+COUNTIF($U$3:U18,U18)-1 -> 22 | X18: CUST0016 | Y18: Deepak Rao | Z18: =SUMIFS(Clean_Data!N2:N1247,Clean_Data!C2:C1247,X18) -> 78933.24 | AA18: =RANK(Z18,$Z$3:$Z$780)+COUNTIF($Z$3:Z18,Z18)-1 -> 27
A19: 2025-06 | B19: =SUMIFS(Clean_Data!N2:N1247,Clean_Data!Q2:Q1247,A19) -> 551833.24 | E19: Rank | F19: Customer | G19: Total Sales | T19: Jeans | U19: =SUMIFS(Clean_Data!N2:N1247,Clean_Data!J2:J1247,T19) -> 66007.24 | V19: =RANK(U19,$U$3:$U$47)+COUNTIF($U$3:U19,U19)-1 -> 26 | X19: CUST0017 | Y19: Suresh Singh | Z19: =SUMIFS(Clean_Data!N2:N1247,Clean_Data!C2:C1247,X19) -> 57393.11 | AA19: =RANK(Z19,$Z$3:$Z$780)+COUNTIF($Z$3:Z19,Z19)-1 -> 41
A20: 2025-07 | B20: =SUMIFS(Clean_Data!N2:N1247,Clean_Data!Q2:Q1247,A20) -> 1097751.4 | E20: 1 | F20: =INDEX($Y$3:$Y$780,MATCH(E20,$AA$3:$AA$780,0))&" ("&INDEX($X$3:$X$780,MATCH(E20,$AA$3:$AA$780,0))&")" -> Ajay Singh (CUST0169) | G20: =INDEX($Z$3:$Z$780,MATCH(E20,$AA$3:$AA$780,0)) -> 222340.22 | T20: Kids Wear | U20: =SUMIFS(Clean_Data!N2:N1247,Clean_Data!J2:J1247,T20) -> 54006.58 | V20: =RANK(U20,$U$3:$U$47)+COUNTIF($U$3:U20,U20)-1 -> 30 | X20: CUST0018 | Y20: Arjun Rao | Z20: =SUMIFS(Clean_Data!N2:N1247,Clean_Data!C2:C1247,X20) -> 66819.31 | AA20: =RANK(Z20,$Z$3:$Z$780)+COUNTIF($Z$3:Z20,Z20)-1 -> 34
A21: 2025-08 | B21: =SUMIFS(Clean_Data!N2:N1247,Clean_Data!Q2:Q1247,A21) -> 714244.19 | E21: 2 | F21: =INDEX($Y$3:$Y$780,MATCH(E21,$AA$3:$AA$780,0))&" ("&INDEX($X$3:$X$780,MATCH(E21,$AA$3:$AA$780,0))&")" -> Anita Malhotra (CUST0171) | G21: =INDEX($Z$3:$Z$780,MATCH(E21,$AA$3:$AA$780,0)) -> 203505.4 | T21: LED Monitor | U21: =SUMIFS(Clean_Data!N2:N1247,Clean_Data!J2:J1247,T21) -> 787030.26 | V21: =RANK(U21,$U$3:$U$47)+COUNTIF($U$3:U21,U21)-1 -> 4 | X21: CUST0019 | Y21: Manisha Agarwal | Z21: =SUMIFS(Clean_Data!N2:N1247,Clean_Data!C2:C1247,X21) -> 3588.15 | AA21: =RANK(Z21,$Z$3:$Z$780)+COUNTIF($Z$3:Z21,Z21)-1 -> 386
A22: 2025-09 | B22: =SUMIFS(Clean_Data!N2:N1247,Clean_Data!Q2:Q1247,A22) -> 801786.99 | E22: 3 | F22: =INDEX($Y$3:$Y$780,MATCH(E22,$AA$3:$AA$780,0))&" ("&INDEX($X$3:$X$780,MATCH(E22,$AA$3:$AA$780,0))&")" -> Anjali Agarwal (CUST0287) | G22: =INDEX($Z$3:$Z$780,MATCH(E22,$AA$3:$AA$780,0)) -> 186655.32 | T22: Laptop | U22: =SUMIFS(Clean_Data!N2:N1247,Clean_Data!J2:J1247,T22) -> 2471093.4 | V22: =RANK(U22,$U$3:$U$47)+COUNTIF($U$3:U22,U22)-1 -> 1 | X22: CUST0020 | Y22: Deepak Choudhury | Z22: =SUMIFS(Clean_Data!N2:N1247,Clean_Data!C2:C1247,X22) -> 1922.2 | AA22: =RANK(Z22,$Z$3:$Z$780)+COUNTIF($Z$3:Z22,Z22)-1 -> 519
A23: 2025-10 | B23: =SUMIFS(Clean_Data!N2:N1247,Clean_Data!Q2:Q1247,A23) -> 1068725.7 | E23: 4 | F23: =INDEX($Y$3:$Y$780,MATCH(E23,$AA$3:$AA$780,0))&" ("&INDEX($X$3:$X$780,MATCH(E23,$AA$3:$AA$780,0))&")" -> Anita Rao (CUST0240) | G23: =INDEX($Z$3:$Z$780,MATCH(E23,$AA$3:$AA$780,0)) -> 175668.46 | T23: Makeup Kit | U23: =SUMIFS(Clean_Data!N2:N1247,Clean_Data!J2:J1247,T23) -> 189308.51 | V23: =RANK(U23,$U$3:$U$47)+COUNTIF($U$3:U23,U23)-1 -> 8 | X23: CUST0021 | Y23: Kritika Kumar | Z23: =SUMIFS(Clean_Data!N2:N1247,Clean_Data!C2:C1247,X23) -> 4173.63 | AA23: =RANK(Z23,$Z$3:$Z$780)+COUNTIF($Z$3:Z23,Z23)-1 -> 352
A24: 2025-11 | B24: =SUMIFS(Clean_Data!N2:N1247,Clean_Data!Q2:Q1247,A24) -> 601269.21 | E24: 5 | F24: =INDEX($Y$3:$Y$780,MATCH(E24,$AA$3:$AA$780,0))&" ("&INDEX($X$3:$X$780,MATCH(E24,$AA$3:$AA$780,0))&")" -> Rohit Singh (CUST0773) | G24: =INDEX($Z$3:$Z$780,MATCH(E24,$AA$3:$AA$780,0)) -> 151694.4 | T24: Men's T-Shirt | U24: =SUMIFS(Clean_Data!N2:N1247,Clean_Data!J2:J1247,T24) -> 29397.77 | V24: =RANK(U24,$U$3:$U$47)+COUNTIF($U$3:U24,U24)-1 -> 41 | X24: CUST0022 | Y24: Vikram Verma | Z24: =SUMIFS(Clean_Data!N2:N1247,Clean_Data!C2:C1247,X24) -> 66322.35 | AA24: =RANK(Z24,$Z$3:$Z$780)+COUNTIF($Z$3:Z24,Z24)-1 -> 36
A25: 2025-12 | B25: =SUMIFS(Clean_Data!N2:N1247,Clean_Data!Q2:Q1247,A25) -> 914786.39 | E25: 6 | F25: =INDEX($Y$3:$Y$780,MATCH(E25,$AA$3:$AA$780,0))&" ("&INDEX($X$3:$X$780,MATCH(E25,$AA$3:$AA$780,0))&")" -> Ravi Menon (CUST0569) | G25: =INDEX($Z$3:$Z$780,MATCH(E25,$AA$3:$AA$780,0)) -> 149297.28 | T25: Mixer Grinder | U25: =SUMIFS(Clean_Data!N2:N1247,Clean_Data!J2:J1247,T25) -> 178908.14 | V25: =RANK(U25,$U$3:$U$47)+COUNTIF($U$3:U25,U25)-1 -> 10 | X25: CUST0023 | Y25: Swati Kumar | Z25: =SUMIFS(Clean_Data!N2:N1247,Clean_Data!C2:C1247,X25) -> 7555.32 | AA25: =RANK(Z25,$Z$3:$Z$780)+COUNTIF($Z$3:Z25,Z25)-1 -> 221
E26: 7 | F26: =INDEX($Y$3:$Y$780,MATCH(E26,$AA$3:$AA$780,0))&" ("&INDEX($X$3:$X$780,MATCH(E26,$AA$3:$AA$780,0))&")" -> Vikram Verma (CUST0256) | G26: =INDEX($Z$3:$Z$780,MATCH(E26,$AA$3:$AA$780,0)) -> 145510.75 | T26: Non-Stick Cookware Set | U26: =SUMIFS(Clean_Data!N2:N1247,Clean_Data!J2:J1247,T26) -> 112056.93 | V26: =RANK(U26,$U$3:$U$47)+COUNTIF($U$3:U26,U26)-1 -> 18 | X26: CUST0024 | Y26: Kritika Menon | Z26: =SUMIFS(Clean_Data!N2:N1247,Clean_Data!C2:C1247,X26) -> 10798.74 | AA26: =RANK(Z26,$Z$3:$Z$780)+COUNTIF($Z$3:Z26,Z26)-1 -> 168
A27: 3. Sales by Product Category | E27: 8 | F27: =INDEX($Y$3:$Y$780,MATCH(E27,$AA$3:$AA$780,0))&" ("&INDEX($X$3:$X$780,MATCH(E27,$AA$3:$AA$780,0))&")" -> Nisha Pillai (CUST0378) | G27: =INDEX($Z$3:$Z$780,MATCH(E27,$AA$3:$AA$780,0)) -> 134176.06 | T27: Notebook Set | U27: =SUMIFS(Clean_Data!N2:N1247,Clean_Data!J2:J1247,T27) -> 20268.43 | V27: =RANK(U27,$U$3:$U$47)+COUNTIF($U$3:U27,U27)-1 -> 44 | X27: CUST0025 | Y27: Swati Nair | Z27: =SUMIFS(Clean_Data!N2:N1247,Clean_Data!C2:C1247,X27) -> 4853.11 | AA27: =RANK(Z27,$Z$3:$Z$780)+COUNTIF($Z$3:Z27,Z27)-1 -> 314
A28: Category | B28: Total Sales | E28: 9 | F28: =INDEX($Y$3:$Y$780,MATCH(E28,$AA$3:$AA$780,0))&" ("&INDEX($X$3:$X$780,MATCH(E28,$AA$3:$AA$780,0))&")" -> Anjali Agarwal (CUST0113) | G28: =INDEX($Z$3:$Z$780,MATCH(E28,$AA$3:$AA$780,0)) -> 124461.77 | T28: Novel | U28: =SUMIFS(Clean_Data!N2:N1247,Clean_Data!J2:J1247,T28) -> 31520.82 | V28: =RANK(U28,$U$3:$U$47)+COUNTIF($U$3:U28,U28)-1 -> 40 | X28: CUST0026 | Y28: Sneha Rao | Z28: =SUMIFS(Clean_Data!N2:N1247,Clean_Data!C2:C1247,X28) -> 5955.75 | AA28: =RANK(Z28,$Z$3:$Z$780)+COUNTIF($Z$3:Z28,Z28)-1 -> 258
A29: Beauty & Personal Care | B29: =SUMIFS(Clean_Data!N2:N1247,Clean_Data!I2:I1247,A29) -> 590934.52 | E29: 10 | F29: =INDEX($Y$3:$Y$780,MATCH(E29,$AA$3:$AA$780,0))&" ("&INDEX($X$3:$X$780,MATCH(E29,$AA$3:$AA$780,0))&")" -> Shreya Nair (CUST0373) | G29: =INDEX($Z$3:$Z$780,MATCH(E29,$AA$3:$AA$780,0)) -> 124327.04 | T29: Perfume | U29: =SUMIFS(Clean_Data!N2:N1247,Clean_Data!J2:J1247,T29) -> 138138.8 | V29: =RANK(U29,$U$3:$U$47)+COUNTIF($U$3:U29,U29)-1 -> 13 | X29: CUST0027 | Y29: Kritika Malhotra | Z29: =SUMIFS(Clean_Data!N2:N1247,Clean_Data!C2:C1247,X29) -> 1522.6 | AA29: =RANK(Z29,$Z$3:$Z$780)+COUNTIF($Z$3:Z29,Z29)-1 -> 561
A30: Books & Stationery | B30: =SUMIFS(Clean_Data!N2:N1247,Clean_Data!I2:I1247,A30) -> 294982.2 | T30: Power Bank | U30: =SUMIFS(Clean_Data!N2:N1247,Clean_Data!J2:J1247,T30) -> 60715.7 | V30: =RANK(U30,$U$3:$U$47)+COUNTIF($U$3:U30,U30)-1 -> 27 | X30: CUST0028 | Y30: Sandeep Malhotra | Z30: =SUMIFS(Clean_Data!N2:N1247,Clean_Data!C2:C1247,X30) -> 15942.86 | AA30: =RANK(Z30,$Z$3:$Z$780)+COUNTIF($Z$3:Z30,Z30)-1 -> 120
A31: Clothing | B31: =SUMIFS(Clean_Data!N2:N1247,Clean_Data!I2:I1247,A31) -> 556158.86 | T31: Rice 5kg | U31: =SUMIFS(Clean_Data!N2:N1247,Clean_Data!J2:J1247,T31) -> 45296.67 | V31: =RANK(U31,$U$3:$U$47)+COUNTIF($U$3:U31,U31)-1 -> 33 | X31: CUST0029 | Y31: Sanjay Verma | Z31: =SUMIFS(Clean_Data!N2:N1247,Clean_Data!C2:C1247,X31) -> 9031.5 | AA31: =RANK(Z31,$Z$3:$Z$780)+COUNTIF($Z$3:Z31,Z31)-1 -> 198
A32: Electronics | B32: =SUMIFS(Clean_Data!N2:N1247,Clean_Data!I2:I1247,A32) -> 5760583 | T32: Saree | U32: =SUMIFS(Clean_Data!N2:N1247,Clean_Data!J2:J1247,T32) -> 72744.22 | V32: =RANK(U32,$U$3:$U$47)+COUNTIF($U$3:U32,U32)-1 -> 23 | X32: CUST0030 | Y32: Naveen Kapoor | Z32: =SUMIFS(Clean_Data!N2:N1247,Clean_Data!C2:C1247,X32) -> 15868.04 | AA32: =RANK(Z32,$Z$3:$Z$780)+COUNTIF($Z$3:Z32,Z32)-1 -> 122
A33: Groceries | B33: =SUMIFS(Clean_Data!N2:N1247,Clean_Data!I2:I1247,A33) -> 152650.26 | T33: Skincare Kit | U33: =SUMIFS(Clean_Data!N2:N1247,Clean_Data!J2:J1247,T33) -> 67368.96 | V33: =RANK(U33,$U$3:$U$47)+COUNTIF($U$3:U33,U33)-1 -> 25 | X33: CUST0031 | Y33: Shreya Menon | Z33: =SUMIFS(Clean_Data!N2:N1247,Clean_Data!C2:C1247,X33) -> 84099.58 | AA33: =RANK(Z33,$Z$3:$Z$780)+COUNTIF($Z$3:Z33,Z33)-1 -> 22
A34: Home & Kitchen | B34: =SUMIFS(Clean_Data!N2:N1247,Clean_Data!I2:I1247,A34) -> 964335.86 | T34: Smartphone | U34: =SUMIFS(Clean_Data!N2:N1247,Clean_Data!J2:J1247,T34) -> 808881.96 | V34: =RANK(U34,$U$3:$U$47)+COUNTIF($U$3:U34,U34)-1 -> 3 | X34: CUST0032 | Y34: Vikram Verma | Z34: =SUMIFS(Clean_Data!N2:N1247,Clean_Data!C2:C1247,X34) -> 2410.23 | AA34: =RANK(Z34,$Z$3:$Z$780)+COUNTIF($Z$3:Z34,Z34)-1 -> 471
A35: Sports & Fitness | B35: =SUMIFS(Clean_Data!N2:N1247,Clean_Data!I2:I1247,A35) -> 713444.65 | T35: Smartwatch | U35: =SUMIFS(Clean_Data!N2:N1247,Clean_Data!J2:J1247,T35) -> 202601.63 | V35: =RANK(U35,$U$3:$U$47)+COUNTIF($U$3:U35,U35)-1 -> 6 | X35: CUST0033 | Y35: Rahul Pillai | Z35: =SUMIFS(Clean_Data!N2:N1247,Clean_Data!C2:C1247,X35) -> 10244.07 | AA35: =RANK(Z35,$Z$3:$Z$780)+COUNTIF($Z$3:Z35,Z35)-1 -> 177
T36: Spice Combo | U36: =SUMIFS(Clean_Data!N2:N1247,Clean_Data!J2:J1247,T36) -> 35615.12 | V36: =RANK(U36,$U$3:$U$47)+COUNTIF($U$3:U36,U36)-1 -> 37 | X36: CUST0034 | Y36: Anita Iyer | Z36: =SUMIFS(Clean_Data!N2:N1247,Clean_Data!C2:C1247,X36) -> 17073.62 | AA36: =RANK(Z36,$Z$3:$Z$780)+COUNTIF($Z$3:Z36,Z36)-1 -> 113
A37: 4. Sales by State | T37: Sports Shoes | U37: =SUMIFS(Clean_Data!N2:N1247,Clean_Data!J2:J1247,T37) -> 136643.59 | V37: =RANK(U37,$U$3:$U$47)+COUNTIF($U$3:U37,U37)-1 -> 14 | X37: CUST0035 | Y37: Rekha Patel | Z37: =SUMIFS(Clean_Data!N2:N1247,Clean_Data!C2:C1247,X37) -> 20564.29 | AA37: =RANK(Z37,$Z$3:$Z$780)+COUNTIF($Z$3:Z37,Z37)-1 -> 95
A38: State | B38: Total Sales | T38: Table Lamp | U38: =SUMIFS(Clean_Data!N2:N1247,Clean_Data!J2:J1247,T38) -> 81800.65 | V38: =RANK(U38,$U$3:$U$47)+COUNTIF($U$3:U38,U38)-1 -> 21 | X38: CUST0036 | Y38: Aishwarya Reddy | Z38: =SUMIFS(Clean_Data!N2:N1247,Clean_Data!C2:C1247,X38) -> 5088.23 | AA38: =RANK(Z38,$Z$3:$Z$780)+COUNTIF($Z$3:Z38,Z38)-1 -> 299
A39: Andhra Pradesh | B39: =SUMIFS(Clean_Data!N2:N1247,Clean_Data!H2:H1247,A39) -> 608833.02 | T39: Tablet | U39: =SUMIFS(Clean_Data!N2:N1247,Clean_Data!J2:J1247,T39) -> 1243905.4 | V39: =RANK(U39,$U$3:$U$47)+COUNTIF($U$3:U39,U39)-1 -> 2 | X39: CUST0037 | Y39: Ritu Mehta | Z39: =SUMIFS(Clean_Data!N2:N1247,Clean_Data!C2:C1247,X39) -> 4727.04 | AA39: =RANK(Z39,$Z$3:$Z$780)+COUNTIF($Z$3:Z39,Z39)-1 -> 319
A40: Delhi | B40: =SUMIFS(Clean_Data!N2:N1247,Clean_Data!H2:H1247,A40) -> 1029550.9 | T40: Tea Pack | U40: =SUMIFS(Clean_Data!N2:N1247,Clean_Data!J2:J1247,T40) -> 23326.95 | V40: =RANK(U40,$U$3:$U$47)+COUNTIF($U$3:U40,U40)-1 -> 42 | X40: CUST0038 | Y40: Rekha Reddy | Z40: =SUMIFS(Clean_Data!N2:N1247,Clean_Data!C2:C1247,X40) -> 31346.15 | AA40: =RANK(Z40,$Z$3:$Z$780)+COUNTIF($Z$3:Z40,Z40)-1 -> 66
...
